INFO     WDM:logger.py:16 xdist worker is: gw0
INFO     WDM:logger.py:16 ====== WebDriver manager ======
INFO     WDM:logger.py:16 Current google-chrome version is 107.0.5304
INFO     WDM:logger.py:16 Get LATEST chromedriver version for 107.0.5304 google-chrome
INFO     WDM:logger.py:16 Driver [/home/vlad/.wdm/gw0/drivers/chromedriver/linux64/107.0.5304.62/chromedriver] found in cache
WARNING  urllib3.connectionpool:connectionpool.py:812 Retrying (Retry(total=2, connect=None, read=None, redirect=None, status=None)) after connection broken by 'NewConnectionError('<urllib3.connection.HTTPConnection object at 0x7fbfc87690d0>: Failed to establish a new connection: [Errno 111] Connection refused')': /session/c906251b1779178df50986fed4eef137/screenshot
WARNING  urllib3.connectionpool:connectionpool.py:812 Retrying (Retry(total=1, connect=None, read=None, redirect=None, status=None)) after connection broken by 'NewConnectionError('<urllib3.connection.HTTPConnection object at 0x7fbfc8769760>: Failed to establish a new connection: [Errno 111] Connection refused')': /session/c906251b1779178df50986fed4eef137/screenshot
WARNING  urllib3.connectionpool:connectionpool.py:812 Retrying (Retry(total=0, connect=None, read=None, redirect=None, status=None)) after connection broken by 'NewConnectionError('<urllib3.connection.HTTPConnection object at 0x7fbfc879fca0>: Failed to establish a new connection: [Errno 111] Connection refused')': /session/c906251b1779178df50986fed4eef137/screenshot
WARNING  urllib3.connectionpool:connectionpool.py:812 Retrying (Retry(total=2, connect=None, read=None, redirect=None, status=None)) after connection broken by 'NewConnectionError('<urllib3.connection.HTTPConnection object at 0x7fbfc8196310>: Failed to establish a new connection: [Errno 111] Connection refused')': /session/c906251b1779178df50986fed4eef137/execute/sync
WARNING  urllib3.connectionpool:connectionpool.py:812 Retrying (Retry(total=1, connect=None, read=None, redirect=None, status=None)) after connection broken by 'NewConnectionError('<urllib3.connection.HTTPConnection object at 0x7fbfc8196d00>: Failed to establish a new connection: [Errno 111] Connection refused')': /session/c906251b1779178df50986fed4eef137/execute/sync
WARNING  urllib3.connectionpool:connectionpool.py:812 Retrying (Retry(total=0, connect=None, read=None, redirect=None, status=None)) after connection broken by 'NewConnectionError('<urllib3.connection.HTTPConnection object at 0x7fbfc8196eb0>: Failed to establish a new connection: [Errno 111] Connection refused')': /session/c906251b1779178df50986fed4eef137/execute/sync